2025-04-02 10:29:44,267 - ERROR - 初期タスク作成中にエラーが発生しました: HTTPConnectionPool(host='redmine', port=3000): Max retries exceeded with url: /projects/1/issues.json?key=d40120a1eebce847fcf8cf84fd667916b28f63cb (Caused by NewConnectionError('<urllib3.connection.HTTPConnection object at 0xffff90ecaf50>: Failed to establish a new connection: [Errno 111] Connection refused'))
2025-04-02 10:32:10,714 - ERROR - 初期タスク作成中にエラーが発生しました: Requested resource doesn't exist
2025-04-02 11:06:27,216 - ERROR - 初期タスク作成中にエラーが発生しました: Requested resource doesn't exist
2025-04-02 11:07:23,317 - ERROR - 初期タスク作成中にエラーが発生しました: Requested resource doesn't exist
2025-04-02 11:28:43,339 - ERROR - タスク '月次報告書作成' の作成中にエラーが発生しました: Redmine returned internal error, check Redmine logs for details
2025-04-02 11:28:43,394 - ERROR - タスク '半期計画書作成' の作成中にエラーが発生しました: Redmine returned internal error, check Redmine logs for details
2025-04-02 11:28:43,397 - ERROR - タスク '週次MTG議事録作成' の作成中にエラーが発生しました: unconverted data remains:  
2025-04-02 11:31:53,255 - ERROR - タスク '月次報告書作成' の作成中にエラーが発生しました: Redmine returned internal error, check Redmine logs for details
2025-04-02 11:31:53,268 - ERROR - タスク '半期計画書作成' の作成中にエラーが発生しました: Redmine returned internal error, check Redmine logs for details
2025-04-02 11:31:53,279 - ERROR - タスク '週次MTG議事録作成' の作成中にエラーが発生しました: Redmine returned internal error, check Redmine logs for details
2025-04-02 11:35:53,692 - INFO - プロジェクト 'SG10' が見つかりました
2025-04-02 11:35:53,702 - ERROR - トラッカーID 1 が見つかりません: Requested resource doesn't exist
